<?xml version="1.0" encoding="UTF-8"?>
<!-- Generated by org.testng.reporters.JUnitReportReporter -->
<testsuite hostname="Admin-PC" name="com.sirma.itt.javacourse.readcons.IntervalExcTest" tests="1" failures="1" timestamp="27 Jun 2014 11:47:52 GMT" time="0.044" errors="0">
  <testcase name="TestInsert" time="0.044" classname="com.sirma.itt.javacourse.readcons.IntervalExcTest">
    <failure type="org.testng.TestException" message="
Expected exception com.sirma.itt.javacourse.readcons.NotInIntervalException but got org.testng.TestException: 
Method IntervalExcTest.TestInsert()[pri:0, instance:com.sirma.itt.javacourse.readcons.IntervalExcTest@2c22f3] should have thrown an exception of class com.sirma.itt.javacourse.readcons.NotInIntervalException">
      <![CDATA[org.testng.TestException: 
Expected exception com.sirma.itt.javacourse.readcons.NotInIntervalException but got org.testng.TestException: 
Method IntervalExcTest.TestInsert()[pri:0, instance:com.sirma.itt.javacourse.readcons.IntervalExcTest@2c22f3] should have thrown an exception of class com.sirma.itt.javacourse.readcons.NotInIntervalException
	at org.testng.internal.Invoker.handleInvocationResults(Invoker.java:1497)
	at org.testng.internal.Invoker.invokeTestMethods(Invoker.java:1245)
	at org.testng.internal.TestMethodWorker.invokeTestMethods(TestMethodWorker.java:127)
	at org.testng.internal.TestMethodWorker.run(TestMethodWorker.java:111)
	at org.testng.TestRunner.privateRun(TestRunner.java:767)
	at org.testng.TestRunner.run(TestRunner.java:617)
	at org.testng.SuiteRunner.runTest(SuiteRunner.java:334)
	at org.testng.SuiteRunner.runSequentially(SuiteRunner.java:329)
	at org.testng.SuiteRunner.privateRun(SuiteRunner.java:291)
	at org.testng.SuiteRunner.run(SuiteRunner.java:240)
	at org.testng.SuiteRunnerWorker.runSuite(SuiteRunnerWorker.java:52)
	at org.testng.SuiteRunnerWorker.run(SuiteRunnerWorker.java:86)
	at org.testng.TestNG.runSuitesSequentially(TestNG.java:1224)
	at org.testng.TestNG.runSuitesLocally(TestNG.java:1149)
	at org.testng.TestNG.run(TestNG.java:1057)
	at org.testng.remote.RemoteTestNG.run(RemoteTestNG.java:111)
	at org.testng.remote.RemoteTestNG.initAndRun(RemoteTestNG.java:204)
	at org.testng.remote.RemoteTestNG.main(RemoteTestNG.java:175)
Caused by: org.testng.TestException: 
Method IntervalExcTest.TestInsert()[pri:0, instance:com.sirma.itt.javacourse.readcons.IntervalExcTest@2c22f3] should have thrown an exception of class com.sirma.itt.javacourse.readcons.NotInIntervalException
	at org.testng.internal.Invoker.handleInvocationResults(Invoker.java:1512)
	at org.testng.internal.Invoker.invokeMethod(Invoker.java:754)
	at org.testng.internal.Invoker.invokeTestMethod(Invoker.java:901)
	at org.testng.internal.Invoker.invokeTestMethods(Invoker.java:1231)
	... 16 more
]]>
    </failure>
  </testcase> <!-- TestInsert -->
</testsuite> <!-- com.sirma.itt.javacourse.readcons.IntervalExcTest -->
